Workbook

Sheet collected_variables_EU
A1: var_name | B1: var_display_name | C1: var_description | D1: var_source_name | E1: var_source_link | F1: var_source_citation | G1: var_source_license | H1: tag_sector | I1: tag_type | J1: tag_commodity | K1: tag_resource | L1: tag_link | M1: tag_other | N1: var_unit | O1: var_aggregation_method | P1: spatial_level | Q1: to_stage? | R1: staging_calculation | S1: post_disagg_calculation_eq | T1: Shruthi's notes | U1: is_used_for_SOIs? | V1: is_used_in_midas_model? | W1: is_used_for_manual_eucalc_disaggregation? | X1: is_used_indirectly_for_disaggregation? | Y1: used_anywhere? | Z1: threshold for rounding down to 0 | AA1: round to integer midas
A2: active_citizenship | B2: Active citizenship | C2: Share of people who claimed they had participated in any of the following activities: activities in a political party or local interest group; public consultation; peaceful protest or demonstration, including signing a petition; writing a letter to a politician or to the media (voting in an election excluded) | D2: EU Social Progress Index - 2020 | E2: https://cohesiondata.ec.europa.eu/stories/s/EU-Social-Progress-Index-2020/8qk9-xq96/ | F2: Paola Annoni and Paolo Bolsi, “EU Social Progress Index - 2020.” https://cohesiondata.ec.europa.eu/stories/s/EU-Social-Progress-Index-2020/8qk9-xq96/ (accessed Aug. 10, 2023). | G2: Creative Commons Attribution 4.0 International (CC BY 4.0) | H2: general stat | N2: percentage | O2: AVG | P2: NUTS0 | Q2: yes | U2: =IF(COUNTIF(soi_input_variables!A:A,A2)>0,"yes","no") -> yes | V2: =IF(COUNTIF(midas_input_variables!A:A,A2)>0,"yes","no") -> no | W2: =IF(OR(COUNTIF(eucalc_variables_proxies!C:C,"*"&A2&"*")>0,COUNTIF(eucalc_variables_proxies!F:F,"*"&A2&"*")>0),"yes","no") -> no | X2: =IF(COUNTIF(collected_variables_proxies!C:C,"*"&A2&"*")>0,"yes","no") -> no | Y2: =IF(OR(U2="yes",V2="yes",W2="yes",X2="yes"),"yes","no") -> yes
A3: agriculture_with_natural_vegetation_cover | B3: Agriculture with natural vegetation cover | C3: Please note that only elements which are at least 25 hectares in area are captured here | D3: Copernicus Land Monitoring Service - Corine Land Cover | E3: https://land.copernicus.eu/pan-european/corine-land-cover/clc2018 | F3: Corine Land Cover, ‘CLC 2018 — Copernicus Land Monitoring Service’. https://land.copernicus.eu/pan-european/corine-land-cover/clc2018 (accessed Nov. 29, 2022). | H3: land use, agriculture and forestry | K3: land area | N3: square kilometer | O3: SUM | P3: LAU | Q3: yes | U3: =IF(COUNTIF(soi_input_variables!A:A,A3)>0,"yes","no") -> yes | V3: =IF(COUNTIF(midas_input_variables!A:A,A3)>0,"yes","no") -> no | W3: =IF(OR(COUNTIF(eucalc_variables_proxies!C:C,"*"&A3&"*")>0,COUNTIF(eucalc_variables_proxies!F:F,"*"&A3&"*")>0),"yes","no") -> yes | X3: =IF(COUNTIF(collected_variables_proxies!C:C,"*"&A3&"*")>0,"yes","no") -> yes | Y3: =IF(OR(U3="yes",V3="yes",W3="yes",X3="yes"),"yes","no") -> yes
A4: agro_forestry_areas_cover | B4: Agro-forestry areas cover | C4: Please note that only elements which are at least 25 hectares in area are captured here | D4: Copernicus Land Monitoring Service - Corine Land Cover | E4: https://land.copernicus.eu/pan-european/corine-land-cover/clc2018 | F4: Corine Land Cover, ‘CLC 2018 — Copernicus Land Monitoring Service’. https://land.copernicus.eu/pan-european/corine-land-cover/clc2018 (accessed Nov. 29, 2022). | H4: land use, agriculture and forestry | K4: land area | N4: square kilometer | O4: SUM | P4: LAU | Q4: yes | U4: =IF(COUNTIF(soi_input_variables!A:A,A4)>0,"yes","no") -> yes | V4: =IF(COUNTIF(midas_input_variables!A:A,A4)>0,"yes","no") -> no | W4: =IF(OR(COUNTIF(eucalc_variables_proxies!C:C,"*"&A4&"*")>0,COUNTIF(eucalc_variables_proxies!F:F,"*"&A4&"*")>0),"yes","no") -> yes | X4: =IF(COUNTIF(collected_variables_proxies!C:C,"*"&A4&"*")>0,"yes","no") -> yes | Y4: =IF(OR(U4="yes",V4="yes",W4="yes",X4="yes"),"yes","no") -> yes
A5: air_transport_of_freight | B5: Air transport of freight | C5: Traffic and transport measurement: Freight loaded and unloaded | D5: Eurostat | E5: https://ec.europa.eu/eurostat/databrowser/view/tran_r_avgo_nm/default/table?lang=en | F5: Eurostat, ‘Air transport of freight by NUTS 2 regions’, 2022. https://ec.europa.eu/eurostat/databrowser/view/tran_r_avgo_nm/default/table?lang=en (accessed Nov. 23, 2022). | G5: Creative Commons Attribution 4.0 International (CC BY 4.0) | H5: transport | I5: cargo | L5: tra_emissions-CO2e_freight_aviation | N5: Mt | O5: SUM | P5: NUTS2 | Q5: yes | U5: =IF(COUNTIF(soi_input_variables!A:A,A5)>0,"yes","no") -> no | V5: =IF(COUNTIF(midas_input_variables!A:A,A5)>0,"yes","no") -> yes | W5: =IF(OR(COUNTIF(eucalc_variables_proxies!C:C,"*"&A5&"*")>0,COUNTIF(eucalc_variables_proxies!F:F,"*"&A5&"*")>0),"yes","no") -> yes | X5: =IF(COUNTIF(collected_variables_proxies!C:C,"*"&A5&"*")>0,"yes","no") -> yes | Y5: =IF(OR(U5="yes",V5="yes",W5="yes",X5="yes"),"yes","no") -> yes
A6: air_transport_of_passengers | B6: Air transport of passengers | C6: Traffic and transport measurement: Passengers carried | D6: Eurostat | E6: https://ec.europa.eu/eurostat/databrowser/view/tgs00077/default/table?lang=en | F6: Eurostat, ‘Air transport of passengers by NUTS 2 regions’, 2022. https://ec.europa.eu/eurostat/databrowser/view/tgs00077/default/table?lang=en (accessed Nov. 23, 2022). | G6: Creative Commons Attribution 4.0 International (CC BY 4.0) | H6: transport | I6: stock | L6: tra_emissions-CO2e_passenger_aviation | N6: number | O6: SUM | P6: NUTS2 | Q6: yes | U6: =IF(COUNTIF(soi_input_variables!A:A,A6)>0,"yes","no") -> no | V6: =IF(COUNTIF(midas_input_variables!A:A,A6)>0,"yes","no") -> yes | W6: =IF(OR(COUNTIF(eucalc_variables_proxies!C:C,"*"&A6&"*")>0,COUNTIF(eucalc_variables_proxies!F:F,"*"&A6&"*")>0),"yes","no") -> yes | X6: =IF(COUNTIF(collected_variables_proxies!C:C,"*"&A6&"*")>0,"yes","no") -> yes | Y6: =IF(OR(U6="yes",V6="yes",W6="yes",X6="yes"),"yes","no") -> yes
A7: airports_cover | B7: Airports cover | C7: Please note that only elements which are at least 25 hectares in area are captured here | D7: Copernicus Land Monitoring Service - Corine Land Cover | E7: https://land.copernicus.eu/pan-european/corine-land-cover/clc2018 | F7: Corine Land Cover, ‘CLC 2018 — Copernicus Land Monitoring Service’. https://land.copernicus.eu/pan-european/corine-land-cover/clc2018 (accessed Nov. 29, 2022). | H7: land use, transport | N7: square kilometer | O7: SUM | P7: LAU | Q7: yes | U7: =IF(COUNTIF(soi_input_variables!A:A,A7)>0,"yes","no") -> no | V7: =IF(COUNTIF(midas_input_variables!A:A,A7)>0,"yes","no") -> no | W7: =IF(OR(COUNTIF(eucalc_variables_proxies!C:C,"*"&A7&"*")>0,COUNTIF(eucalc_variables_proxies!F:F,"*"&A7&"*")>0),"yes","no") -> yes | X7: =IF(COUNTIF(collected_variables_proxies!C:C,"*"&A7&"*")>0,"yes","no") -> yes | Y7: =IF(OR(U7="yes",V7="yes",W7="yes",X7="yes"),"yes","no") -> yes
A8: animal_and_mixed_food_and_vegetal_waste | B8: Animal and mixed food and vegetal waste | D8: Eurostat | E8: https://ec.europa.eu/eurostat/databrowser/view/ENV_WASGEN/default/table?lang=en | F8: Eurostat, “Generation of waste by waste category, hazardousness and NACE Rev. 2 activity.” Accessed: Oct. 04, 2023. [Online]. Available: https://ec.europa.eu/eurostat/databrowser/view/ENV_WASGEN/default/table?lang=en | G8: Creative Commons Attribution 4.0 International (CC BY 4.0) | H8: waste | N8: kilogram | O8: SUM | P8: NUTS0 | Q8: yes | U8: =IF(COUNTIF(soi_input_variables!A:A,A8)>0,"yes","no") -> yes | V8: =IF(COUNTIF(midas_input_variables!A:A,A8)>0,"yes","no") -> no | W8: =IF(OR(COUNTIF(eucalc_variables_proxies!C:C,"*"&A8&"*")>0,COUNTIF(eucalc_variables_proxies!F:F,"*"&A8&"*")>0),"yes","no") -> no | X8: =IF(COUNTIF(collected_variables_proxies!C:C,"*"&A8&"*")>0,"yes","no") -> no | Y8: =IF(OR(U8="yes",V8="yes",W8="yes",X8="yes"),"yes","no") -> yes
A9: cproj_annual_mean_maximum_temperature | B9: Annual mean of daily maximum temperature | C9: Daily maximum temperature averaged over a year | D9: EURO-CORDEX: new high-resolution climate change projections for European impact research | E9: https://www.euro-cordex.net/060378/index.php.en | F9: D. Jacob et al., ‘EURO-CORDEX: new high-resolution climate change projections for European impact research’, Regional environmental change, vol. 14, no. 2, pp. 563–578, 2014. | H9: weather and climate | N9: degree celsius | O9: AVG | P9: NUTS3 | Q9: yes | U9: =IF(COUNTIF(soi_input_variables!A:A,A9)>0,"yes","no") -> no | V9: =IF(COUNTIF(midas_input_variables!A:A,A9)>0,"yes","no") -> no | W9: =IF(OR(COUNTIF(eucalc_variables_proxies!C:C,"*"&A9&"*")>0,COUNTIF(eucalc_variables_proxies!F:F,"*"&A9&"*")>0),"yes","no") -> no | X9: =IF(COUNTIF(collected_variables_proxies!C:C,"*"&A9&"*")>0,"yes","no") -> no | Y9: =IF(OR(U9="yes",V9="yes",W9="yes",X9="yes"),"yes","no") -> no | Z9: 0.1
A10: cproj_annual_mean_mean_temperature | B10: Annual mean of daily mean temperature | C10: Daily mean temperature averaged over a year | D10: EURO-CORDEX: new high-resolution climate change projections for European impact research | E10: https://www.euro-cordex.net/060378/index.php.en | F10: D. Jacob et al., ‘EURO-CORDEX: new high-resolution climate change projections for European impact research’, Regional environmental change, vol. 14, no. 2, pp. 563–578, 2014. | H10: weather and climate | N10: degree celsius | O10: AVG | P10: NUTS3 | Q10: yes | U10: =IF(COUNTIF(soi_input_variables!A:A,A10)>0,"yes","no") -> no | V10: =IF(COUNTIF(midas_input_variables!A:A,A10)>0,"yes","no") -> no | W10: =IF(OR(COUNTIF(eucalc_variables_proxies!C:C,"*"&A10&"*")>0,COUNTIF(eucalc_variables_proxies!F:F,"*"&A10&"*")>0),"yes","no") -> no | X10: =IF(COUNTIF(collected_variables_proxies!C:C,"*"&A10&"*")>0,"yes","no") -> no | Y10: =IF(OR(U10="yes",V10="yes",W10="yes",X10="yes"),"yes","no") -> no | Z10: 0.1
A11: cproj_annual_mean_minimum_temperature | B11: Annual mean of daily minimum temperature | C11: Daily minimum temperature averaged over a year | D11: EURO-CORDEX: new high-resolution climate change projections for European impact research | E11: https://www.euro-cordex.net/060378/index.php.en | F11: D. Jacob et al., ‘EURO-CORDEX: new high-resolution climate change projections for European impact research’, Regional environmental change, vol. 14, no. 2, pp. 563–578, 2014. | H11: weather and climate | N11: degree celsius | O11: AVG | P11: NUTS3 | Q11: yes | U11: =IF(COUNTIF(soi_input_variables!A:A,A11)>0,"yes","no") -> no | V11: =IF(COUNTIF(midas_input_variables!A:A,A11)>0,"yes","no") -> no | W11: =IF(OR(COUNTIF(eucalc_variables_proxies!C:C,"*"&A11&"*")>0,COUNTIF(eucalc_variables_proxies!F:F,"*"&A11&"*")>0),"yes","no") -> no | X11: =IF(COUNTIF(collected_variables_proxies!C:C,"*"&A11&"*")>0,"yes","no") -> no | Y11: =IF(OR(U11="yes",V11="yes",W11="yes",X11="yes"),"yes","no") -> no | Z11: 0.1
A12: cproj_annual_mean_precipitation | B12: Annual mean precipitation | C12: Daily precipitation averaged over a year | D12: EURO-CORDEX: new high-resolution climate change projections for European impact research | E12: https://www.euro-cordex.net/060378/index.php.en | F12: D. Jacob et al., ‘EURO-CORDEX: new high-resolution climate change projections for European impact research’, Regional environmental change, vol. 14, no. 2, pp. 563–578, 2014. | H12: weather and climate | N12: mm/day | O12: AVG | P12: NUTS3 | Q12: yes | U12: =IF(COUNTIF(soi_input_variables!A:A,A12)>0,"yes","no") -> no | V12: =IF(COUNTIF(midas_input_variables!A:A,A12)>0,"yes","no") -> no | W12: =IF(OR(COUNTIF(eucalc_variables_proxies!C:C,"*"&A12&"*")>0,COUNTIF(eucalc_variables_proxies!F:F,"*"&A12&"*")>0),"yes","no") -> no | X12: =IF(COUNTIF(collected_variables_proxies!C:C,"*"&A12&"*")>0,"yes","no") -> no | Y12: =IF(OR(U12="yes",V12="yes",W12="yes",X12="yes"),"yes","no") -> no | Z12: 0.1
A13: cproj_annual_total_precipitation | B13: Annual total precipitation | C13: Daily precipitation summed over a year | D13: EURO-CORDEX: new high-resolution climate change projections for European impact research | E13: https://www.euro-cordex.net/060378/index.php.en | F13: D. Jacob et al., ‘EURO-CORDEX: new high-resolution climate change projections for European impact research’, Regional environmental change, vol. 14, no. 2, pp. 563–578, 2014. | H13: weather and climate | N13: mm | O13: AVG | P13: NUTS3 | Q13: yes | U13: =IF(COUNTIF(soi_input_variables!A:A,A13)>0,"yes","no") -> no | V13: =IF(COUNTIF(midas_input_variables!A:A,A13)>0,"yes","no") -> no | W13: =IF(OR(COUNTIF(eucalc_variables_proxies!C:C,"*"&A13&"*")>0,COUNTIF(eucalc_variables_proxies!F:F,"*"&A13&"*")>0),"yes","no") -> no | X13: =IF(COUNTIF(collected_variables_proxies!C:C,"*"&A13&"*")>0,"yes","no") -> no | Y13: =IF(OR(U13="yes",V13="yes",W13="yes",X13="yes"),"yes","no") -> no | Z13: 0.1
A14: aquaculture_area | B14: Aquaculture area | D14: OpenStreetMap | E14: https://download.geofabrik.de/ | F14: OpenStreetMap contributors (2017). Planet dump retrieved from https://planet.osm.org . https://www. openstreetmap.org. | G14: Open Data Commons Open Database License (ODbL) | H14: land use, water | N14: square kilometer | O14: SUM | P14: LAU | Q14: yes | U14: =IF(COUNTIF(soi_input_variables!A:A,A14)>0,"yes","no") -> no | V14: =IF(COUNTIF(midas_input_variables!A:A,A14)>0,"yes","no") -> no | W14: =IF(OR(COUNTIF(eucalc_variables_proxies!C:C,"*"&A14&"*")>0,COUNTIF(eucalc_variables_proxies!F:F,"*"&A14&"*")>0),"yes","no") -> no | X14: =IF(COUNTIF(collected_variables_proxies!C:C,"*"&A14&"*")>0,"yes","no") -> no | Y14: =IF(OR(U14="yes",V14="yes",W14="yes",X14="yes"),"yes","no") -> no
A15: area | B15: Area | D15: GISCO - Eurostat | E15: https://ec.europa.eu/eurostat/web/gisco/geodata/statistical-units/local-administrative-units | F15: GISCO - Eurostat, ‘NUTS - GISCO - Eurostat’, 2021. https://ec.europa.eu/eurostat/web/gisco/geodata/reference-data/administrative-units-statistical-units/lau (accessed Nov. 23, 2022). | G15: Creative Commons Attribution 4.0 International (CC BY 4.0) | H15: general stat | N15: square kilometer | O15: SUM | P15: LAU | Q15: yes | U15: =IF(COUNTIF(soi_input_variables!A:A,A15)>0,"yes","no") -> yes | V15: =IF(COUNTIF(midas_input_variables!A:A,A15)>0,"yes","no") -> no | W15: =IF(OR(COUNTIF(eucalc_variables_proxies!C:C,"*"&A15&"*")>0,COUNTIF(eucalc_variables_proxies!F:F,"*"&A15&"*")>0),"yes","no") -> yes | X15: =IF(COUNTIF(collected_variables_proxies!C:C,"*"&A15&"*")>0,"yes","no") -> yes | Y15: =IF(OR(U15="yes",V15="yes",W15="yes",X15="yes"),"yes","no") -> yes
A16: average_air_pollution_due_to_no2 | B16: Average air pollution due to NO2 | D16: European Environmental Agency | E16: https://www.eea.europa.eu/en/datahub/datahubitem-view/34bd02bf-be87-4122-b9a2-1e846c27a786 | F16: European Environment Agency. “NO2, European Air Quality Data, (Interpolated Data).” Accessed July 16, 2024. https://www.eea.europa.eu/en/datahub/datahubitem-view/34bd02bf-be87-4122-b9a2-1e846c27a786. | G16: Creative Commons Attribution 4.0 International (CC BY 4.0) | H16: environmental and biodiversity | N16: ug/m3 | O16: AVG | P16: LAU | Q16: yes | U16: =IF(COUNTIF(soi_input_variables!A:A,A16)>0,"yes","no") -> yes | V16: =IF(COUNTIF(midas_input_variables!A:A,A16)>0,"yes","no") -> no | W16: =IF(OR(COUNTIF(eucalc_variables_proxies!C:C,"*"&A16&"*")>0,COUNTIF(eucalc_variables_proxies!F:F,"*"&A16&"*")>0),"yes","no") -> no | X16: =IF(COUNTIF(collected_variables_proxies!C:C,"*"&A16&"*")>0,"yes","no") -> yes | Y16: =IF(OR(U16="yes",V16="yes",W16="yes",X16="yes"),"yes","no") -> yes
A17: average_air_pollution_due_to_o3 | B17: Average air pollution due to O3 | D17: European Environmental Agency | E17: https://www.eea.europa.eu/en/datahub/datahubitem-view/c816f363-a892-4f62-86d1-0460437bc023 | F17: European Environment Agency. “O3, European Air Quality Data, (Interpolated Data).” Accessed July 16, 2024. https://www.eea.europa.eu/en/datahub/datahubitem-view/c816f363-a892-4f62-86d1-0460437bc023. | G17: Creative Commons Attribution 4.0 International (CC BY 4.0) | H17: environmental and biodiversity | N17: ug/m3 | O17: AVG | P17: LAU | Q17: yes | U17: =IF(COUNTIF(soi_input_variables!A:A,A17)>0,"yes","no") -> yes | V17: =IF(COUNTIF(midas_input_variables!A:A,A17)>0,"yes","no") -> no | W17: =IF(OR(COUNTIF(eucalc_variables_proxies!C:C,"*"&A17&"*")>0,COUNTIF(eucalc_variables_proxies!F:F,"*"&A17&"*")>0),"yes","no") -> no | X17: =IF(COUNTIF(collected_variables_proxies!C:C,"*"&A17&"*")>0,"yes","no") -> yes | Y17: =IF(OR(U17="yes",V17="yes",W17="yes",X17="yes"),"yes","no") -> yes
A18: average_air_pollution_due_to_pm10 | B18: Average air pollution due to PM10 | D18: European Environmental Agency | E18: https://www.eea.europa.eu/en/datahub/datahubitem-view/abc66a42-b595-4e0f-9772-b862dc454e9f | F18: European Environment Agency. “PM10, European Air Quality Data, (Interpolated Data).” Accessed July 16, 2024. https://www.eea.europa.eu/en/datahub/datahubitem-view/abc66a42-b595-4e0f-9772-b862dc454e9f. | G18: Creative Commons Attribution 4.0 International (CC BY 4.0) | H18: environmental and biodiversity | N18: ug/m3 | O18: AVG | P18: LAU | Q18: yes | U18: =IF(COUNTIF(soi_input_variables!A:A,A18)>0,"yes","no") -> no | V18: =IF(COUNTIF(midas_input_variables!A:A,A18)>0,"yes","no") -> no | W18: =IF(OR(COUNTIF(eucalc_variables_proxies!C:C,"*"&A18&"*")>0,COUNTIF(eucalc_variables_proxies!F:F,"*"&A18&"*")>0),"yes","no") -> no | X18: =IF(COUNTIF(collected_variables_proxies!C:C,"*"&A18&"*")>0,"yes","no") -> no | Y18: =IF(OR(U18="yes",V18="yes",W18="yes",X18="yes"),"yes","no") -> no
A19: average_air_pollution_due_to_pm25 | B19: Average air pollution due to PM2.5 | C19: Particulate matter 2.5 | D19: European Environmental Agency | E19: https://www.eea.europa.eu/en/datahub/datahubitem-view/938bea70-07fc-47e9-8559-8a09f7f92494 | F19: European Environment Agency. “Pm25, European Air Quality Data, (Interpolated Data).” Accessed July 16, 2024. https://www.eea.europa.eu/en/datahub/datahubitem-view/938bea70-07fc-47e9-8559-8a09f7f92494. | G19: Creative Commons Attribution 4.0 International (CC BY 4.0) | H19: environmental and biodiversity | N19: ug/m3 | O19: AVG | P19: LAU | Q19: yes | U19: =IF(COUNTIF(soi_input_variables!A:A,A19)>0,"yes","no") -> yes | V19: =IF(COUNTIF(midas_input_variables!A:A,A19)>0,"yes","no") -> no | W19: =IF(OR(COUNTIF(eucalc_variables_proxies!C:C,"*"&A19&"*")>0,COUNTIF(eucalc_variables_proxies!F:F,"*"&A19&"*")>0),"yes","no") -> no | X19: =IF(COUNTIF(collected_variables_proxies!C:C,"*"&A19&"*")>0,"yes","no") -> yes | Y19: =IF(OR(U19="yes",V19="yes",W19="yes",X19="yes"),"yes","no") -> yes
A20: bare_rocks_cover | B20: Bare rocks cover | C20: Please note that only elements which are at least 25 hectares in area are captured here | D20: Copernicus Land Monitoring Service - Corine Land Cover | E20: https://land.copernicus.eu/pan-european/corine-land-cover/clc2018 | F20: Corine Land Cover, ‘CLC 2018 — Copernicus Land Monitoring Service’. https://land.copernicus.eu/pan-european/corine-land-cover/clc2018 (accessed Nov. 29, 2022). | H20: land use | K20: land area | N20: square kilometer | O20: SUM | P20: LAU | Q20: yes | U20: =IF(COUNTIF(soi_input_variables!A:A,A20)>0,"yes","no") -> no | V20: =IF(COUNTIF(midas_input_variables!A:A,A20)>0,"yes","no") -> yes | W20: =IF(OR(COUNTIF(eucalc_variables_proxies!C:C,"*"&A20&"*")>0,COUNTIF(eucalc_variables_proxies!F:F,"*"&A20&"*")>0),"yes","no") -> no | X20: =IF(COUNTIF(collected_variables_proxies!C:C,"*"&A20&"*")>0,"yes","no") -> no | Y20: =IF(OR(U20="yes",V20="yes",W20="yes",X20="yes"),"yes","no") -> yes
A21: beaches_dunes_and_sand_cover | B21: Beaches, dunes, and sand cover | C21: Please note that only elements which are at least 25 hectares in area are captured here | D21: Copernicus Land Monitoring Service - Corine Land Cover | E21: https://land.copernicus.eu/pan-european/corine-land-cover/clc2018 | F21: Corine Land Cover, ‘CLC 2018 — Copernicus Land Monitoring Service’. https://land.copernicus.eu/pan-european/corine-land-cover/clc2018 (accessed Nov. 29, 2022). | H21: land use, water | K21: coastal area | N21: square kilometer | O21: SUM | P21: LAU | Q21: yes | U21: =IF(COUNTIF(soi_input_variables!A:A,A21)>0,"yes","no") -> no | V21: =IF(COUNTIF(midas_input_variables!A:A,A21)>0,"yes","no") -> yes | W21: =IF(OR(COUNTIF(eucalc_variables_proxies!C:C,"*"&A21&"*")>0,COUNTIF(eucalc_variables_proxies!F:F,"*"&A21&"*")>0),"yes","no") -> no | X21: =IF(COUNTIF(collected_variables_proxies!C:C,"*"&A21&"*")>0,"yes","no") -> no | Y21: =IF(OR(U21="yes",V21="yes",W21="yes",X21="yes"),"yes","no") -> yes
A22: broad_leaved_forest_cover | B22: Broad-leaved forest cover | C22: Please note that only elements which are at least 25 hectares in area are captured here | D22: Copernicus Land Monitoring Service - Corine Land Cover | E22: https://land.copernicus.eu/pan-european/corine-land-cover/clc2018 | F22: Corine Land Cover, ‘CLC 2018 — Copernicus Land Monitoring Service’. https://land.copernicus.eu/pan-european/corine-land-cover/clc2018 (accessed Nov. 29, 2022). | H22: land use, agriculture and forestry | K22: land area | N22: square kilometer | O22: SUM | P22: LAU | Q22: yes | U22: =IF(COUNTIF(soi_input_variables!A:A,A22)>0,"yes","no") -> yes | V22: =IF(COUNTIF(midas_input_variables!A:A,A22)>0,"yes","no") -> no | W22: =IF(OR(COUNTIF(eucalc_variables_proxies!C:C,"*"&A22&"*")>0,COUNTIF(eucalc_variables_proxies!F:F,"*"&A22&"*")>0),"yes","no") -> yes | X22: =IF(COUNTIF(collected_variables_proxies!C:C,"*"&A22&"*")>0,"yes","no") -> no | Y22: =IF(OR(U22="yes",V22="yes",W22="yes",X22="yes"),"yes","no") -> yes
A23: burnt_areas_cover | B23: Burnt areas cover | C23: Please note that only elements which are at least 25 hectares in area are captured here | D23: Copernicus Land Monitoring Service - Corine Land Cover | E23: https://land.copernicus.eu/pan-european/corine-land-cover/clc2018 | F23: Corine Land Cover, ‘CLC 2018 — Copernicus Land Monitoring Service’. https://land.copernicus.eu/pan-european/corine-land-cover/clc2018 (accessed Nov. 29, 2022). | H23: land use | K23: land area | N23: square kilometer | O23: SUM | P23: LAU | Q23: yes | U23: =IF(COUNTIF(soi_input_variables!A:A,A23)>0,"yes","no") -> no | V23: =IF(COUNTIF(midas_input_variables!A:A,A23)>0,"yes","no") -> yes | W23: =IF(OR(COUNTIF(eucalc_variables_proxies!C:C,"*"&A23&"*")>0,COUNTIF(eucalc_variables_proxies!F:F,"*"&A23&"*")>0),"yes","no") -> yes | X23: =IF(COUNTIF(collected_variables_proxies!C:C,"*"&A23&"*")>0,"yes","no") -> no | Y23: =IF(OR(U23="yes",V23="yes",W23="yes",X23="yes"),"yes","no") -> yes
A24: business_investment | B24: Business investment | C24: The indicator gives the share of GDP that is used for business investment (rather than being used for e.g. consumption or exports). | D24: Eurostat | E24: https://ec.europa.eu/eurostat/databrowser/view/tec00132/default/table?lang=en | F24: Eurostat, ‘Investment by institutional sectors’, 2022. https://ec.europa.eu/eurostat/databrowser/view/tec00132/default/table?lang=en (accessed Nov. 23, 2022). | G24: Creative Commons Attribution 4.0 International (CC BY 4.0) | H24: general stat | I24: investment | N24: percentage | O24: AVG | P24: NUTS0 | Q24: yes | U24: =IF(COUNTIF(soi_input_variables!A:A,A24)>0,"yes","no") -> no | V24: =IF(COUNTIF(midas_input_variables!A:A,A24)>0,"yes","no") -> no | W24: =IF(OR(COUNTIF(eucalc_variables_proxies!C:C,"*"&A24&"*")>0,COUNTIF(eucalc_variables_proxies!F:F,"*"&A24&"*")>0),"yes","no") -> no | X24: =IF(COUNTIF(collected_variables_proxies!C:C,"*"&A24&"*")>0,"yes","no") -> no | Y24: =IF(OR(U24="yes",V24="yes",W24="yes",X24="yes"),"yes","no") -> no
A25: capital_stock_based_productivity_in_agriculture | B25: Capital stock-based productivity in agriculture | C25: Calculated by: Gross value added/input capital stock. Unit is index, base period for productivity measurement is 2015. | D25: Eurostat | E25: https://ec.europa.eu/eurostat/databrowser/view/nama_10_cp_a21/default/table?lang=en | F25: Eurostat, ‘Capital stock based productivity indicators at industry level’, 2022. https://ec.europa.eu/eurostat/databrowser/view/nama_10_cp_a21/default/table?lang=en (accessed Nov. 23, 2022). | G25: Creative Commons Attribution 4.0 International (CC BY 4.0) | H25: general stat, agriculture and forestry | I25: finance | N25: index | O25: AVG | P25: NUTS0 | Q25: yes | U25: =IF(COUNTIF(soi_input_variables!A:A,A25)>0,"yes","no") -> no | V25: =IF(COUNTIF(midas_input_variables!A:A,A25)>0,"yes","no") -> no | W25: =IF(OR(COUNTIF(eucalc_variables_proxies!C:C,"*"&A25&"*")>0,COUNTIF(eucalc_variables_proxies!F:F,"*"&A25&"*")>0),"yes","no") -> no | X25: =IF(COUNTIF(collected_variables_proxies!C:C,"*"&A25&"*")>0,"yes","no") -> no | Y25: =IF(OR(U25="yes",V25="yes",W25="yes",X25="yes"),"yes","no") -> no
A26: capital_stock_based_productivity_in_manufacturing | B26: Capital stock-based productivity in manufacturing | C26: Calculated by: Gross value added/input capital stock. Unit is index, base period for productivity measurement is 2015. | D26: Eurostat | E26: https://ec.europa.eu/eurostat/databrowser/view/nama_10_cp_a21/default/table?lang=en | F26: Eurostat, ‘Capital stock based productivity indicators at industry level’, 2022. https://ec.europa.eu/eurostat/databrowser/view/nama_10_cp_a21/default/table?lang=en (accessed Nov. 23, 2022). | G26: Creative Commons Attribution 4.0 International (CC BY 4.0) | H26: general stat, industry | I26: finance | N26: index | O26: AVG | P26: NUTS0 | Q26: yes | U26: =IF(COUNTIF(soi_input_variables!A:A,A26)>0,"yes","no") -> no | V26: =IF(COUNTIF(midas_input_variables!A:A,A26)>0,"yes","no") -> no | W26: =IF(OR(COUNTIF(eucalc_variables_proxies!C:C,"*"&A26&"*")>0,COUNTIF(eucalc_variables_proxies!F:F,"*"&A26&"*")>0),"yes","no") -> no | X26: =IF(COUNTIF(collected_variables_proxies!C:C,"*"&A26&"*")>0,"yes","no") -> no | Y26: =IF(OR(U26="yes",V26="yes",W26="yes",X26="yes"),"yes","no") -> no
A27: capital_stock_based_productivity_in_transportation | B27: Capital stock-based productivity in transportation | C27: Calculated by: Gross value added/input capital stock. Unit is index, base period for productivity measurement is 2015. | D27: Eurostat | E27: https://ec.europa.eu/eurostat/databrowser/view/nama_10_cp_a21/default/table?lang=en | F27: Eurostat, ‘Capital stock based productivity indicators at industry level’, 2022. https://ec.europa.eu/eurostat/databrowser/view/nama_10_cp_a21/default/table?lang=en (accessed Nov. 23, 2022). | G27: Creative Commons Attribution 4.0 International (CC BY 4.0) | H27: general stat, transport, service | I27: finance | N27: index | O27: AVG | P27: NUTS0 | Q27: yes | U27: =IF(COUNTIF(soi_input_variables!A:A,A27)>0,"yes","no") -> no | V27: =IF(COUNTIF(midas_input_variables!A:A,A27)>0,"yes","no") -> no | W27: =IF(OR(COUNTIF(eucalc_variables_proxies!C:C,"*"&A27&"*")>0,COUNTIF(eucalc_variables_proxies!F:F,"*"&A27&"*")>0),"yes","no") -> no | X27: =IF(COUNTIF(collected_variables_proxies!C:C,"*"&A27&"*")>0,"yes","no") -> no | Y27: =IF(OR(U27="yes",V27="yes",W27="yes",X27="yes"),"yes","no") -> no
A28: cimp_change_in_frequency_of_coldwaves_maximum | B28: Change in frequency of coldwaves -maximum | C28: Projected change summer coldwave days frequency and time frame, rescaled by max Values and their meanings: 1 = Increase, 0 = No Change, -1 = Decrease, -5 = Uncertain, -10 = Not Known | D28: EURO-CORDEX: new high-resolution climate change projections for European impact research | E28: https://www.euro-cordex.net/060378/index.php.en | F28: D. Jacob et al., ‘EURO-CORDEX: new high-resolution climate change projections for European impact research’, Regional environmental change, vol. 14, no. 2, pp. 563–578, 2014. | H28: climate hazard | I28: frequency | M28: coldwave | N28: (categorical) | O28: MAX | P28: NUTS3 | Q28: yes | U28: =IF(COUNTIF(soi_input_variables!A:A,A28)>0,"yes","no") -> no | V28: =IF(COUNTIF(midas_input_variables!A:A,A28)>0,"yes","no") -> no | W28: =IF(OR(COUNTIF(eucalc_variables_proxies!C:C,"*"&A28&"*")>0,COUNTIF(eucalc_variables_proxies!F:F,"*"&A28&"*")>0),"yes","no") -> no | X28: =IF(COUNTIF(collected_variables_proxies!C:C,"*"&A28&"*")>0,"yes","no") -> no | Y28: =IF(OR(U28="yes",V28="yes",W28="yes",X28="yes"),"yes","no") -> no
A29: cimp_change_in_frequency_of_coldwaves_mean | B29: Change in frequency of coldwaves -mean | C29: Projected change summer coldwave days frequency and time frame, rescaled by mean Values and their meanings: 1 = Increase, 0 = No Change, -1 = Decrease, -5 = Uncertain, -10 = Not Known | D29: EURO-CORDEX: new high-resolution climate change projections for European impact research | E29: https://www.euro-cordex.net/060378/index.php.en | F29: D. Jacob et al., ‘EURO-CORDEX: new high-resolution climate change projections for European impact research’, Regional environmental change, vol. 14, no. 2, pp. 563–578, 2014. | H29: climate hazard | I29: frequency | N29: (categorical) | O29: MAX | P29: NUTS3 | Q29: yes | U29: =IF(COUNTIF(soi_input_variables!A:A,A29)>0,"yes","no") -> yes | V29: =IF(COUNTIF(midas_input_variables!A:A,A29)>0,"yes","no") -> no | W29: =IF(OR(COUNTIF(eucalc_variables_proxies!C:C,"*"&A29&"*")>0,COUNTIF(eucalc_variables_proxies!F:F,"*"&A29&"*")>0),"yes","no") -> no | X29: =IF(COUNTIF(collected_variables_proxies!C:C,"*"&A29&"*")>0,"yes","no") -> no | Y29: =IF(OR(U29="yes",V29="yes",W29="yes",X29="yes"),"yes","no") -> yes
A30: cimp_change_in_frequency_of_extreme_drought_maximum | B30: Change in frequency of extreme drought - maximum | C30: Projected change in frequency of extreme drought days (2021-2100) and time frame, rescaled by max Values and their meanings: 1 = Increase, 0 = No Change, -1 = Decrease, -5 = Uncertain, -10 = Not Known | D30: EURO-CORDEX: new high-resolution climate change projections for European impact research | E30: https://www.euro-cordex.net/060378/index.php.en | F30: D. Jacob et al., ‘EURO-CORDEX: new high-resolution climate change projections for European impact research’, Regional environmental change, vol. 14, no. 2, pp. 563–578, 2014. | H30: climate hazard | I30: frequency | N30: (categorical) | O30: MAX | P30: NUTS3 | Q30: yes | U30: =IF(COUNTIF(soi_input_variables!A:A,A30)>0,"yes","no") -> no | V30: =IF(COUNTIF(midas_input_variables!A:A,A30)>0,"yes","no") -> no | W30: =IF(OR(COUNTIF(eucalc_variables_proxies!C:C,"*"&A30&"*")>0,COUNTIF(eucalc_variables_proxies!F:F,"*"&A30&"*")>0),"yes","no") -> no | X30: =IF(COUNTIF(collected_variables_proxies!C:C,"*"&A30&"*")>0,"yes","no") -> no | Y30: =IF(OR(U30="yes",V30="yes",W30="yes",X30="yes"),"yes","no") -> no
A31: cimp_change_in_frequency_of_extreme_drought_mean | B31: Change in frequency of extreme drought - mean | C31: Projected change in frequency of extreme drought days (2021-2100) and time frame, rescaled by mean Values and their meanings: 1 = Increase, 0 = No Change, -1 = Decrease, -5 = Uncertain, -10 = Not Known | D31: EURO-CORDEX: new high-resolution climate change projections for European impact research | E31: https://www.euro-cordex.net/060378/index.php.en | F31: D. Jacob et al., ‘EURO-CORDEX: new high-resolution climate change projections for European impact research’, Regional environmental change, vol. 14, no. 2, pp. 563–578, 2014. | H31: climate hazard | I31: frequency | N31: (categorical) | O31: MAX | P31: NUTS3 | Q31: yes | U31: =IF(COUNTIF(soi_input_variables!A:A,A31)>0,"yes","no") -> no | V31: =IF(COUNTIF(midas_input_variables!A:A,A31)>0,"yes","no") -> no | W31: =IF(OR(COUNTIF(eucalc_variables_proxies!C:C,"*"&A31&"*")>0,COUNTIF(eucalc_variables_proxies!F:F,"*"&A31&"*")>0),"yes","no") -> no | X31: =IF(COUNTIF(collected_variables_proxies!C:C,"*"&A31&"*")>0,"yes","no") -> no | Y31: =IF(OR(U31="yes",V31="yes",W31="yes",X31="yes"),"yes","no") -> no
A32: cimp_change_in_frequency_of_heatwaves_maximum | B32: Change in frequency of heatwaves -maximum | C32: Projected change summer heatwave days frequency and time frame, rescaled by max Values and their meanings: 1 = Increase, 0 = No Change, -1 = Decrease, -5 = Uncertain, -10 = Not Known | D32: EURO-CORDEX: new high-resolution climate change projections for European impact research | E32: https://www.euro-cordex.net/060378/index.php.en | F32: D. Jacob et al., ‘EURO-CORDEX: new high-resolution climate change projections for European impact research’, Regional environmental change, vol. 14, no. 2, pp. 563–578, 2014. | H32: climate hazard | I32: frequency | N32: (categorical) | O32: MAX | P32: NUTS3 | Q32: yes | U32: =IF(COUNTIF(soi_input_variables!A:A,A32)>0,"yes","no") -> no | V32: =IF(COUNTIF(midas_input_variables!A:A,A32)>0,"yes","no") -> no | W32: =IF(OR(COUNTIF(eucalc_variables_proxies!C:C,"*"&A32&"*")>0,COUNTIF(eucalc_variables_proxies!F:F,"*"&A32&"*")>0),"yes","no") -> no | X32: =IF(COUNTIF(collected_variables_proxies!C:C,"*"&A32&"*")>0,"yes","no") -> no | Y32: =IF(OR(U32="yes",V32="yes",W32="yes",X32="yes"),"yes","no") -> no
A33: cimp_change_in_frequency_of_heatwaves_mean | B33: Change in frequency of heatwaves -mean | C33: Projected change summer heatwave days frequency and time frame, rescaled by mean Values and their meanings: 1 = Increase, 0 = No Change, -1 = Decrease, -5 = Uncertain, -10 = Not Known | D33: EURO-CORDEX: new high-resolution climate change projections for European impact research | E33: https://www.euro-cordex.net/060378/index.php.en | F33: D. Jacob et al., ‘EURO-CORDEX: new high-resolution climate change projections for European impact research’, Regional environmental change, vol. 14, no. 2, pp. 563–578, 2014. | H33: climate hazard | I33: frequency | N33: (categorical) | O33: MAX | P33: NUTS3 | Q33: yes | U33: =IF(COUNTIF(soi_input_variables!A:A,A33)>0,"yes","no") -> yes | V33: =IF(COUNTIF(midas_input_variables!A:A,A33)>0,"yes","no") -> no | W33: =IF(OR(COUNTIF(eucalc_variables_proxies!C:C,"*"&A33&"*")>0,COUNTIF(eucalc_variables_proxies!F:F,"*"&A33&"*")>0),"yes","no") -> no | X33: =IF(COUNTIF(collected_variables_proxies!C:C,"*"&A33&"*")>0,"yes","no") -> no | Y33: =IF(OR(U33="yes",V33="yes",W33="yes",X33="yes"),"yes","no") -> yes
A34: cimp_change_in_frequency_of_heavy_precipitation_maximum | B34: Change in frequency of heavy precipitation - maximum | C34: Projected change of frequency of days (2021-2100) with precipitation >20mm and time frame, rescaled by max Values and their meanings: 1 = Increase, 0 = No Change, -1 = Decrease, -5 = Uncertain, -10 = Not Known | D34: EURO-CORDEX: new high-resolution climate change projections for European impact research | E34: https://www.euro-cordex.net/060378/index.php.en | F34: D. Jacob et al., ‘EURO-CORDEX: new high-resolution climate change projections for European impact research’, Regional environmental change, vol. 14, no. 2, pp. 563–578, 2014. | H34: climate hazard | I34: frequency | N34: (categorical) | O34: MAX | P34: NUTS3 | Q34: yes | U34: =IF(COUNTIF(soi_input_variables!A:A,A34)>0,"yes","no") -> no | V34: =IF(COUNTIF(midas_input_variables!A:A,A34)>0,"yes","no") -> no | W34: =IF(OR(COUNTIF(eucalc_variables_proxies!C:C,"*"&A34&"*")>0,COUNTIF(eucalc_variables_proxies!F:F,"*"&A34&"*")>0),"yes","no") -> no | X34: =IF(COUNTIF(collected_variables_proxies!C:C,"*"&A34&"*")>0,"yes","no") -> no | Y34: =IF(OR(U34="yes",V34="yes",W34="yes",X34="yes"),"yes","no") -> no
A35: cimp_change_in_frequency_of_heavy_precipitation_mean | B35: Change in frequency of heavy precipitation - mean | C35: Projected change of frequency of days with precipitation >20mm and time frame,rescaled by mean Values and their meanings: 1 = Increase, 0 = No Change, -1 = Decrease, -5 = Uncertain, -10 = Not Known | D35: EURO-CORDEX: new high-resolution climate change projections for European impact research | E35: https://www.euro-cordex.net/060378/index.php.en | F35: D. Jacob et al., ‘EURO-CORDEX: new high-resolution climate change projections for European impact research’, Regional environmental change, vol. 14, no. 2, pp. 563–578, 2014. | H35: climate hazard | I35: frequency | N35: (categorical) | O35: MAX | P35: NUTS3 | Q35: yes | U35: =IF(COUNTIF(soi_input_variables!A:A,A35)>0,"yes","no") -> yes | V35: =IF(COUNTIF(midas_input_variables!A:A,A35)>0,"yes","no") -> no | W35: =IF(OR(COUNTIF(eucalc_variables_proxies!C:C,"*"&A35&"*")>0,COUNTIF(eucalc_variables_proxies!F:F,"*"&A35&"*")>0),"yes","no") -> no | X35: =IF(COUNTIF(collected_variables_proxies!C:C,"*"&A35&"*")>0,"yes","no") -> no | Y35: =IF(OR(U35="yes",V35="yes",W35="yes",X35="yes"),"yes","no") -> yes
A36: cimp_change_in_frequency_of_high_fire_risk_maximum | B36: Change in frequency of high fire risk -maximum | C36: Projected change of frequency of a summer day (2021-2100) with high fire risk and time frame, rescaled by max Values and their meanings: 1 = Increase, 0 = No Change, -1 = Decrease, -5 = Uncertain, -10 = Not Known | D36: EURO-CORDEX: new high-resolution climate change projections for European impact research | E36: https://www.euro-cordex.net/060378/index.php.en | F36: D. Jacob et al., ‘EURO-CORDEX: new high-resolution climate change projections for European impact research’, Regional environmental change, vol. 14, no. 2, pp. 563–578, 2014. | H36: climate hazard | I36: frequency | N36: (categorical) | O36: MAX | P36: NUTS3 | Q36: yes | U36: =IF(COUNTIF(soi_input_variables!A:A,A36)>0,"yes","no") -> no | V36: =IF(COUNTIF(midas_input_variables!A:A,A36)>0,"yes","no") -> no | W36: =IF(OR(COUNTIF(eucalc_variables_proxies!C:C,"*"&A36&"*")>0,COUNTIF(eucalc_variables_proxies!F:F,"*"&A36&"*")>0),"yes","no") -> no | X36: =IF(COUNTIF(collected_variables_proxies!C:C,"*"&A36&"*")>0,"yes","no") -> no | Y36: =IF(OR(U36="yes",V36="yes",W36="yes",X36="yes"),"yes","no") -> no
A37: cimp_change_in_frequency_of_high_fire_risk_mean | B37: Change in frequency of high fire risk -mean | C37: Projected change of frequency of a summer day (2021-2100) with high fire risk and time frame, rescaled by mean Values and their meanings: 1 = Increase, 0 = No Change, -1 = Decrease, -5 = Uncertain, -10 = Not Known | D37: EURO-CORDEX: new high-resolution climate change projections for European impact research | E37: https://www.euro-cordex.net/060378/index.php.en | F37: D. Jacob et al., ‘EURO-CORDEX: new high-resolution climate change projections for European impact research’, Regional environmental change, vol. 14, no. 2, pp. 563–578, 2014. | H37: climate hazard | I37: frequency | N37: (categorical) | O37: MAX | P37: NUTS3 | Q37: yes | U37: =IF(COUNTIF(soi_input_variables!A:A,A37)>0,"yes","no") -> yes | V37: =IF(COUNTIF(midas_input_variables!A:A,A37)>0,"yes","no") -> no | W37: =IF(OR(COUNTIF(eucalc_variables_proxies!C:C,"*"&A37&"*")>0,COUNTIF(eucalc_variables_proxies!F:F,"*"&A37&"*")>0),"yes","no") -> no | X37: =IF(COUNTIF(collected_variables_proxies!C:C,"*"&A37&"*")>0,"yes","no") -> no | Y37: =IF(OR(U37="yes",V37="yes",W37="yes",X37="yes"),"yes","no") -> yes
A38: cimp_change_in_frequency_of_moderate_fire_risk_maximum | B38: Change in frequency of moderate fire risk - maximum | C38: Projected change of frequency of a summer day (2021-2100) with moderate fire risk and time frame, rescaled by max Values and their meanings: 1 = Increase, 0 = No Change, -1 = Decrease, -5 = Uncertain, -10 = Not Known | D38: EURO-CORDEX: new high-resolution climate change projections for European impact research | E38: https://www.euro-cordex.net/060378/index.php.en | F38: D. Jacob et al., ‘EURO-CORDEX: new high-resolution climate change projections for European impact research’, Regional environmental change, vol. 14, no. 2, pp. 563–578, 2014. | H38: climate hazard | I38: frequency | N38: (categorical) | O38: MAX | P38: NUTS3 | Q38: yes | U38: =IF(COUNTIF(soi_input_variables!A:A,A38)>0,"yes","no") -> no | V38: =IF(COUNTIF(midas_input_variables!A:A,A38)>0,"yes","no") -> no | W38: =IF(OR(COUNTIF(eucalc_variables_proxies!C:C,"*"&A38&"*")>0,COUNTIF(eucalc_variables_proxies!F:F,"*"&A38&"*")>0),"yes","no") -> no | X38: =IF(COUNTIF(collected_variables_proxies!C:C,"*"&A38&"*")>0,"yes","no") -> no | Y38: =IF(OR(U38="yes",V38="yes",W38="yes",X38="yes"),"yes","no") -> no
A39: cimp_change_in_frequency_of_moderate_fire_risk_mean | B39: Change in frequency of moderate fire risk - mean | C39: Projected change of frequency of a summer day (2021-2100) with moderate fire risk and time frame, rescaled by mean Values and their meanings: 1 = Increase, 0 = No Change, -1 = Decrease, -5 = Uncertain, -10 = Not Known | D39: EURO-CORDEX: new high-resolution climate change projections for European impact research | E39: https://www.euro-cordex.net/060378/index.php.en | F39: D. Jacob et al., ‘EURO-CORDEX: new high-resolution climate change projections for European impact research’, Regional environmental change, vol. 14, no. 2, pp. 563–578, 2014. | H39: climate hazard | I39: frequency | N39: (categorical) | O39: MAX | P39: NUTS3 | Q39: yes | U39: =IF(COUNTIF(soi_input_variables!A:A,A39)>0,"yes","no") -> no | V39: =IF(COUNTIF(midas_input_variables!A:A,A39)>0,"yes","no") -> no | W39: =IF(OR(COUNTIF(eucalc_variables_proxies!C:C,"*"&A39&"*")>0,COUNTIF(eucalc_variables_proxies!F:F,"*"&A39&"*")>0),"yes","no") -> no | X39: =IF(COUNTIF(collected_variables_proxies!C:C,"*"&A39&"*")>0,"yes","no") -> no | Y39: =IF(OR(U39="yes",V39="yes",W39="yes",X39="yes"),"yes","no") -> no
A40: cimp_change_in_frequency_of_very_high_fire_risk_maximum | B40: Change in frequency of very high fire risk -maximum | C40: Projected change of frequency of a summer day (2021-2100) with very high fire risk and time frame, rescaled by max Values and their meanings: 1 = Increase, 0 = No Change, -1 = Decrease, -5 = Uncertain, -10 = Not Known | D40: EURO-CORDEX: new high-resolution climate change projections for European impact research | E40: https://www.euro-cordex.net/060378/index.php.en | F40: D. Jacob et al., ‘EURO-CORDEX: new high-resolution climate change projections for European impact research’, Regional environmental change, vol. 14, no. 2, pp. 563–578, 2014. | H40: climate hazard | I40: frequency | N40: (categorical) | O40: MAX | P40: NUTS3 | Q40: yes | U40: =IF(COUNTIF(soi_input_variables!A:A,A40)>0,"yes","no") -> no | V40: =IF(COUNTIF(midas_input_variables!A:A,A40)>0,"yes","no") -> no | W40: =IF(OR(COUNTIF(eucalc_variables_proxies!C:C,"*"&A40&"*")>0,COUNTIF(eucalc_variables_proxies!F:F,"*"&A40&"*")>0),"yes","no") -> no | X40: =IF(COUNTIF(collected_variables_proxies!C:C,"*"&A40&"*")>0,"yes","no") -> no | Y40: =IF(OR(U40="yes",V40="yes",W40="yes",X40="yes"),"yes","no") -> no
...

Sheet collected_variables_proxies
B1: EU
A2: var_name | B2: disaggregation_binary_criteria | C2: disaggregation_proxy | D2: proxy_reasoning | E2: use_random_forest_model? | F2: proxy_confidence_level
A3: population_age_less_than_5 | C3: population | E3: yes | F3: 3
A4: population_age_between_5_and_9 | C4: population | E4: yes | F4: 3
A5: population_age_between_10_and_14 | C5: population | E5: yes | F5: 3
A6: population_age_between_15_and_19 | C6: population | E6: yes | F6: 3
A7: population_age_between_20_and_24 | C7: population | E7: yes | F7: 3
A8: population_age_between_25_and_29 | C8: population | E8: yes | F8: 3
A9: population_age_between_30_and_34 | C9: population | E9: yes | F9: 3
A10: population_age_between_35_and_39 | C10: population | E10: yes | F10: 3
A11: population_age_between_40_and_44 | C11: population | E11: yes | F11: 3
A12: population_age_between_45_and_49 | C12: population | E12: yes | F12: 3
A13: population_age_between_50_and_54 | C13: population | E13: yes | F13: 3
A14: population_age_between_55_and_59 | C14: population | E14: yes | F14: 3
... A368: heat_production_with_electricity | C368: generation_capacity_of_other_plants | E368: no | F368: 4
A369: residential_final_energy_consumption_from_anthracite | C369: population*cproj_annual_mean_temperature_heating_degree_days | F369: 2
A370: residential_final_energy_consumption_from_coking_coal | C370: population*cproj_annual_mean_temperature_heating_degree_days | F370: 2
A371: residential_final_energy_consumption_from_other_bituminous_coal | C371: population*cproj_annual_mean_temperature_heating_degree_days | F371: 2
A372: residential_final_energy_consumption_from_sub_bituminous_coal | C372: population*cproj_annual_mean_temperature_heating_degree_days | F372: 2
A373: residential_final_energy_consumption_from_lignite | C373: population*cproj_annual_mean_temperature_heating_degree_days | F373: 2
A374: residential_final_energy_consumption_from_coke_oven_coke | C374: population*cproj_annual_mean_temperature_heating_degree_days | F374: 2
A375: residential_final_energy_consumption_from_gas_coke | C375: population*cproj_annual_mean_temperature_heating_degree_days | F375: 2
A376: residential_final_energy_consumption_from_patent_fuel | C376: population*cproj_annual_mean_temperature_heating_degree_days | F376: 2
A377: residential_final_energy_consumption_from_brown_coal_briquettes | C377: population*cproj_annual_mean_temperature_heating_degree_days | F377: 2
A378: residential_final_energy_consumption_from_coal_tar | C378: population*cproj_annual_mean_temperature_heating_degree_days | F378: 2
A379: residential_final_energy_consumption_from_coke_oven_gas | C379: population*cproj_annual_mean_temperature_heating_degree_days | F379: 2
A380: residential_final_energy_consumption_from_gas_works_gas | C380: population*cproj_annual_mean_temperature_heating_degree_days | F380: 2
... A433: energy_demand_in_agriculture_and_forestry_and_fisheries_from_geothermal | C433: gross_value_added_nace_sector_a | F433: 2
A434: energy_demand_in_transport_from_blended_biodiesels | C434: gross_value_added_nace_sector_g_i | E434: no | F434: 4
A435: energy_demand_in_transport_from_liquefied_petroleum_gases | C435: gross_value_added_nace_sector_g_i | E435: no | F435: 4
A436: energy_demand_in_transport_from_blended_biogasoline | C436: gross_value_added_nace_sector_g_i | E436: no | F436: 4
A437: energy_demand_in_transport_from_pure_biogasoline | C437: gross_value_added_nace_sector_g_i | E437: no | F437: 4
A438: final_energy_consumption_from_manufacture_of_paper_and_paper_products_using_liquefied_petroleum_gases | C438: number_of_paper_and_printing_industries | F438: 3
A439: final_energy_consumption_from_manufacture_of_paper_and_paper_products_using_fuel_oil | C439: number_of_paper_and_printing_industries | F439: 3
A440: final_energy_consumption_from_manufacture_of_paper_and_paper_products_using_gas_oil_and_diesel_oil | C440: number_of_paper_and_printing_industries | F440: 3
A441: final_energy_consumption_from_manufacture_of_paper_and_paper_products_using_motor_gasoline | C441: number_of_paper_and_printing_industries | F441: 3
A442: final_energy_consumption_from_manufacture_of_paper_and_paper_products_using_anthracite | C442: number_of_paper_and_printing_industries | F442: 3
A443: final_energy_consumption_from_manufacture_of_paper_and_paper_products_using_coking_coal | C443: number_of_paper_and_printing_industries | F443: 3
A444: final_energy_consumption_from_manufacture_of_paper_and_paper_products_using_other_bituminous_coal | C444: number_of_paper_and_printing_industries | F444: 3
A445: final_energy_consumption_from_manufacture_of_paper_and_paper_products_using_sub_bituminous_coal | C445: number_of_paper_and_printing_industries | F445: 3
...

Sheet deleted_variables
A1: final_energy_consumption_from_anthracite | B1: final_energy_consumption_from_anthracite | C1: final_energy_consumption_from_anthracite | D1: https://ec.europa.eu/eurostat/databrowser/view/NRG_BAL_C/default/table?lang=en | E1: Eurostat, “Complete energy balances,” Apr. 28, 2023. https://ec.europa.eu/eurostat/databrowser/view/NRG_BAL_C/default/table?lang=en (accessed Aug. 01, 2023). | F1: Creative Commons Attribution 4.0 International (CC BY 4.0) | G1: energy | H1: demand | M1: MWh | N1: SUM | O1: NUTS0 | P1: no | S1: 27 | T1: 0 | U1: =ROUND(T1/S1*100,2) -> 0 | W1: =IF(COUNTIF(soi_input_variables!A:A,A1)>0,"yes","no") -> no | X1: =IF(COUNTIF(midas_input_variables!A:A,A1)>0,"yes","no") -> no | Y1: =IF(OR(COUNTIF(eucalc_variables_proxies!C:C,"*"&A1&"*")>0,COUNTIF(eucalc_variables_proxies!F:F,"*"&A1&"*")>0),"yes","no") -> no | Z1: =IF(COUNTIF(collected_variables_proxies!C:C,"*"&A1&"*")>0,"yes","no") -> no | AA1: =IF(OR(W1="yes",X1="yes",Y1="yes",Z1="yes"),"yes","no") -> no | AB1: 500
A2: final_energy_consumption_from_coking_coal | B2: final_energy_consumption_from_coking_coal | C2: final_energy_consumption_from_coking_coal | D2: https://ec.europa.eu/eurostat/databrowser/view/NRG_BAL_C/default/table?lang=en | E2: Eurostat, “Complete energy balances,” Apr. 28, 2023. https://ec.europa.eu/eurostat/databrowser/view/NRG_BAL_C/default/table?lang=en (accessed Aug. 01, 2023). | F2: Creative Commons Attribution 4.0 International (CC BY 4.0) | G2: energy | H2: demand | M2: MWh | N2: SUM | O2: NUTS0 | P2: no | S2: 27 | T2: 0 | U2: =ROUND(T2/S2*100,2) -> 0 | W2: =IF(COUNTIF(soi_input_variables!A:A,A2)>0,"yes","no") -> no | X2: =IF(COUNTIF(midas_input_variables!A:A,A2)>0,"yes","no") -> no | Y2: =IF(OR(COUNTIF(eucalc_variables_proxies!C:C,"*"&A2&"*")>0,COUNTIF(eucalc_variables_proxies!F:F,"*"&A2&"*")>0),"yes","no") -> no | Z2: =IF(COUNTIF(collected_variables_proxies!C:C,"*"&A2&"*")>0,"yes","no") -> no | AA2: =IF(OR(W2="yes",X2="yes",Y2="yes",Z2="yes"),"yes","no") -> no | AB2: 500
A3: final_energy_consumption_from_lignite | B3: final_energy_consumption_from_lignite | C3: final_energy_consumption_from_lignite | D3: https://ec.europa.eu/eurostat/databrowser/view/NRG_BAL_C/default/table?lang=en | E3: Eurostat, “Complete energy balances,” Apr. 28, 2023. https://ec.europa.eu/eurostat/databrowser/view/NRG_BAL_C/default/table?lang=en (accessed Aug. 01, 2023). | F3: Creative Commons Attribution 4.0 International (CC BY 4.0) | G3: energy | H3: demand | M3: MWh | N3: SUM | O3: NUTS0 | P3: no | S3: 27 | T3: 0 | U3: =ROUND(T3/S3*100,2) -> 0 | W3: =IF(COUNTIF(soi_input_variables!A:A,A3)>0,"yes","no") -> no | X3: =IF(COUNTIF(midas_input_variables!A:A,A3)>0,"yes","no") -> no | Y3: =IF(OR(COUNTIF(eucalc_variables_proxies!C:C,"*"&A3&"*")>0,COUNTIF(eucalc_variables_proxies!F:F,"*"&A3&"*")>0),"yes","no") -> no | Z3: =IF(COUNTIF(collected_variables_proxies!C:C,"*"&A3&"*")>0,"yes","no") -> no | AA3: =IF(OR(W3="yes",X3="yes",Y3="yes",Z3="yes"),"yes","no") -> no | AB3: 500
A4: final_energy_consumption_from_other_bituminous_coal | B4: final_energy_consumption_from_other_bituminous_coal | C4: final_energy_consumption_from_other_bituminous_coal | D4: https://ec.europa.eu/eurostat/databrowser/view/NRG_BAL_C/default/table?lang=en | E4: Eurostat, “Complete energy balances,” Apr. 28, 2023. https://ec.europa.eu/eurostat/databrowser/view/NRG_BAL_C/default/table?lang=en (accessed Aug. 01, 2023). | F4: Creative Commons Attribution 4.0 International (CC BY 4.0) | G4: energy | H4: demand | M4: MWh | N4: SUM | O4: NUTS0 | P4: no | S4: 27 | T4: 0 | U4: =ROUND(T4/S4*100,2) -> 0 | W4: =IF(COUNTIF(soi_input_variables!A:A,A4)>0,"yes","no") -> no | X4: =IF(COUNTIF(midas_input_variables!A:A,A4)>0,"yes","no") -> no | Y4: =IF(OR(COUNTIF(eucalc_variables_proxies!C:C,"*"&A4&"*")>0,COUNTIF(eucalc_variables_proxies!F:F,"*"&A4&"*")>0),"yes","no") -> no | Z4: =IF(COUNTIF(collected_variables_proxies!C:C,"*"&A4&"*")>0,"yes","no") -> no | AA4: =IF(OR(W4="yes",X4="yes",Y4="yes",Z4="yes"),"yes","no") -> no | AB4: 500
A5: final_energy_consumption_from_sub_bituminous_coal | B5: final_energy_consumption_from_sub_bituminous_coal | C5: final_energy_consumption_from_sub_bituminous_coal | D5: https://ec.europa.eu/eurostat/databrowser/view/NRG_BAL_C/default/table?lang=en | E5: Eurostat, “Complete energy balances,” Apr. 28, 2023. https://ec.europa.eu/eurostat/databrowser/view/NRG_BAL_C/default/table?lang=en (accessed Aug. 01, 2023). | F5: Creative Commons Attribution 4.0 International (CC BY 4.0) | G5: energy | H5: demand | M5: MWh | N5: SUM | O5: NUTS0 | P5: no | S5: 27 | T5: 0 | U5: =ROUND(T5/S5*100,2) -> 0 | W5: =IF(COUNTIF(soi_input_variables!A:A,A5)>0,"yes","no") -> no | X5: =IF(COUNTIF(midas_input_variables!A:A,A5)>0,"yes","no") -> no | Y5: =IF(OR(COUNTIF(eucalc_variables_proxies!C:C,"*"&A5&"*")>0,COUNTIF(eucalc_variables_proxies!F:F,"*"&A5&"*")>0),"yes","no") -> no | Z5: =IF(COUNTIF(collected_variables_proxies!C:C,"*"&A5&"*")>0,"yes","no") -> no | AA5: =IF(OR(W5="yes",X5="yes",Y5="yes",Z5="yes"),"yes","no") -> no | AB5: 500
A6: final_energy_consumption_from_coke_oven_coke | B6: final_energy_consumption_from_coke_oven_coke | C6: final_energy_consumption_from_coke_oven_coke | D6: https://ec.europa.eu/eurostat/databrowser/view/NRG_BAL_C/default/table?lang=en | E6: Eurostat, “Complete energy balances,” Apr. 28, 2023. https://ec.europa.eu/eurostat/databrowser/view/NRG_BAL_C/default/table?lang=en (accessed Aug. 01, 2023). | F6: Creative Commons Attribution 4.0 International (CC BY 4.0) | G6: energy | H6: demand | M6: MWh | N6: SUM | O6: NUTS0 | P6: no | S6: 27 | T6: 0 | U6: =ROUND(T6/S6*100,2) -> 0 | W6: =IF(COUNTIF(soi_input_variables!A:A,A6)>0,"yes","no") -> no | X6: =IF(COUNTIF(midas_input_variables!A:A,A6)>0,"yes","no") -> no | Y6: =IF(OR(COUNTIF(eucalc_variables_proxies!C:C,"*"&A6&"*")>0,COUNTIF(eucalc_variables_proxies!F:F,"*"&A6&"*")>0),"yes","no") -> no | Z6: =IF(COUNTIF(collected_variables_proxies!C:C,"*"&A6&"*")>0,"yes","no") -> no | AA6: =IF(OR(W6="yes",X6="yes",Y6="yes",Z6="yes"),"yes","no") -> no | AB6: 500
A7: final_energy_consumption_from_gas_coke | B7: final_energy_consumption_from_gas_coke | C7: final_energy_consumption_from_gas_coke | D7: https://ec.europa.eu/eurostat/databrowser/view/NRG_BAL_C/default/table?lang=en | E7: Eurostat, “Complete energy balances,” Apr. 28, 2023. https://ec.europa.eu/eurostat/databrowser/view/NRG_BAL_C/default/table?lang=en (accessed Aug. 01, 2023). | F7: Creative Commons Attribution 4.0 International (CC BY 4.0) | G7: energy | H7: demand | M7: MWh | N7: SUM | O7: NUTS0 | P7: no | S7: 27 | T7: 0 | U7: =ROUND(T7/S7*100,2) -> 0 | W7: =IF(COUNTIF(soi_input_variables!A:A,A7)>0,"yes","no") -> no | X7: =IF(COUNTIF(midas_input_variables!A:A,A7)>0,"yes","no") -> no | Y7: =IF(OR(COUNTIF(eucalc_variables_proxies!C:C,"*"&A7&"*")>0,COUNTIF(eucalc_variables_proxies!F:F,"*"&A7&"*")>0),"yes","no") -> no | Z7: =IF(COUNTIF(collected_variables_proxies!C:C,"*"&A7&"*")>0,"yes","no") -> no | AA7: =IF(OR(W7="yes",X7="yes",Y7="yes",Z7="yes"),"yes","no") -> no | AB7: 500
A8: final_energy_consumption_from_patent_fuel | B8: final_energy_consumption_from_patent_fuel | C8: final_energy_consumption_from_patent_fuel | D8: https://ec.europa.eu/eurostat/databrowser/view/NRG_BAL_C/default/table?lang=en | E8: Eurostat, “Complete energy balances,” Apr. 28, 2023. https://ec.europa.eu/eurostat/databrowser/view/NRG_BAL_C/default/table?lang=en (accessed Aug. 01, 2023). | F8: Creative Commons Attribution 4.0 International (CC BY 4.0) | G8: energy | H8: demand | M8: MWh | N8: SUM | O8: NUTS0 | P8: no | S8: 27 | T8: 0 | U8: =ROUND(T8/S8*100,2) -> 0 | W8: =IF(COUNTIF(soi_input_variables!A:A,A8)>0,"yes","no") -> no | X8: =IF(COUNTIF(midas_input_variables!A:A,A8)>0,"yes","no") -> no | Y8: =IF(OR(COUNTIF(eucalc_variables_proxies!C:C,"*"&A8&"*")>0,COUNTIF(eucalc_variables_proxies!F:F,"*"&A8&"*")>0),"yes","no") -> no | Z8: =IF(COUNTIF(collected_variables_proxies!C:C,"*"&A8&"*")>0,"yes","no") -> no | AA8: =IF(OR(W8="yes",X8="yes",Y8="yes",Z8="yes"),"yes","no") -> no | AB8: 500
A9: final_energy_consumption_from_brown_coal_briquettes | B9: final_energy_consumption_from_brown_coal_briquettes | C9: final_energy_consumption_from_brown_coal_briquettes | D9: https://ec.europa.eu/eurostat/databrowser/view/NRG_BAL_C/default/table?lang=en | E9: Eurostat, “Complete energy balances,” Apr. 28, 2023. https://ec.europa.eu/eurostat/databrowser/view/NRG_BAL_C/default/table?lang=en (accessed Aug. 01, 2023). | F9: Creative Commons Attribution 4.0 International (CC BY 4.0) | G9: energy | H9: demand | M9: MWh | N9: SUM | O9: NUTS0 | P9: no | S9: 27 | T9: 0 | U9: =ROUND(T9/S9*100,2) -> 0 | W9: =IF(COUNTIF(soi_input_variables!A:A,A9)>0,"yes","no") -> no | X9: =IF(COUNTIF(midas_input_variables!A:A,A9)>0,"yes","no") -> no | Y9: =IF(OR(COUNTIF(eucalc_variables_proxies!C:C,"*"&A9&"*")>0,COUNTIF(eucalc_variables_proxies!F:F,"*"&A9&"*")>0),"yes","no") -> no | Z9: =IF(COUNTIF(collected_variables_proxies!C:C,"*"&A9&"*")>0,"yes","no") -> no | AA9: =IF(OR(W9="yes",X9="yes",Y9="yes",Z9="yes"),"yes","no") -> no | AB9: 500
A10: final_energy_consumption_from_coal_tar | B10: final_energy_consumption_from_coal_tar | C10: final_energy_consumption_from_coal_tar | D10: https://ec.europa.eu/eurostat/databrowser/view/NRG_BAL_C/default/table?lang=en | E10: Eurostat, “Complete energy balances,” Apr. 28, 2023. https://ec.europa.eu/eurostat/databrowser/view/NRG_BAL_C/default/table?lang=en (accessed Aug. 01, 2023). | F10: Creative Commons Attribution 4.0 International (CC BY 4.0) | G10: energy | H10: demand | M10: MWh | N10: SUM | O10: NUTS0 | P10: no | S10: 27 | T10: 0 | U10: =ROUND(T10/S10*100,2) -> 0 | W10: =IF(COUNTIF(soi_input_variables!A:A,A10)>0,"yes","no") -> no | X10: =IF(COUNTIF(midas_input_variables!A:A,A10)>0,"yes","no") -> no | Y10: =IF(OR(COUNTIF(eucalc_variables_proxies!C:C,"*"&A10&"*")>0,COUNTIF(eucalc_variables_proxies!F:F,"*"&A10&"*")>0),"yes","no") -> no | Z10: =IF(COUNTIF(collected_variables_proxies!C:C,"*"&A10&"*")>0,"yes","no") -> no | AA10: =IF(OR(W10="yes",X10="yes",Y10="yes",Z10="yes"),"yes","no") -> no | AB10: 500
A11: final_energy_consumption_from_coke_oven_gas | B11: final_energy_consumption_from_coke_oven_gas | C11: final_energy_consumption_from_coke_oven_gas | D11: https://ec.europa.eu/eurostat/databrowser/view/NRG_BAL_C/default/table?lang=en | E11: Eurostat, “Complete energy balances,” Apr. 28, 2023. https://ec.europa.eu/eurostat/databrowser/view/NRG_BAL_C/default/table?lang=en (accessed Aug. 01, 2023). | F11: Creative Commons Attribution 4.0 International (CC BY 4.0) | G11: energy | H11: demand | M11: MWh | N11: SUM | O11: NUTS0 | P11: no | S11: 27 | T11: 0 | U11: =ROUND(T11/S11*100,2) -> 0 | W11: =IF(COUNTIF(soi_input_variables!A:A,A11)>0,"yes","no") -> no | X11: =IF(COUNTIF(midas_input_variables!A:A,A11)>0,"yes","no") -> no | Y11: =IF(OR(COUNTIF(eucalc_variables_proxies!C:C,"*"&A11&"*")>0,COUNTIF(eucalc_variables_proxies!F:F,"*"&A11&"*")>0),"yes","no") -> no | Z11: =IF(COUNTIF(collected_variables_proxies!C:C,"*"&A11&"*")>0,"yes","no") -> no | AA11: =IF(OR(W11="yes",X11="yes",Y11="yes",Z11="yes"),"yes","no") -> no | AB11: 500
A12: final_energy_consumption_from_gas_works_gas | B12: final_energy_consumption_from_gas_works_gas | C12: final_energy_consumption_from_gas_works_gas | D12: https://ec.europa.eu/eurostat/databrowser/view/NRG_BAL_C/default/table?lang=en | E12: Eurostat, “Complete energy balances,” Apr. 28, 2023. https://ec.europa.eu/eurostat/databrowser/view/NRG_BAL_C/default/table?lang=en (accessed Aug. 01, 2023). | F12: Creative Commons Attribution 4.0 International (CC BY 4.0) | G12: energy | H12: demand | M12: MWh | N12: SUM | O12: NUTS0 | P12: no | S12: 27 | T12: 0 | U12: =ROUND(T12/S12*100,2) -> 0 | W12: =IF(COUNTIF(soi_input_variables!A:A,A12)>0,"yes","no") -> no | X12: =IF(COUNTIF(midas_input_variables!A:A,A12)>0,"yes","no") -> no | Y12: =IF(OR(COUNTIF(eucalc_variables_proxies!C:C,"*"&A12&"*")>0,COUNTIF(eucalc_variables_proxies!F:F,"*"&A12&"*")>0),"yes","no") -> no | Z12: =IF(COUNTIF(collected_variables_proxies!C:C,"*"&A12&"*")>0,"yes","no") -> no | AA12: =IF(OR(W12="yes",X12="yes",Y12="yes",Z12="yes"),"yes","no") -> no | AB12: 500
